package com.example.coroutine.coroutineexceptionshandling

import kotlinx.coroutines.CoroutineExceptionHandler
import kotlinx.coroutines.CoroutineScope
import kotlinx.coroutines.SupervisorJob
import kotlinx.coroutines.delay
import kotlinx.coroutines.launch
import kotlinx.coroutines.runBlocking

fun main() = runBlocking {
    val supervisor = SupervisorJob()
    with(CoroutineScope(coroutineContext + supervisor)) {
        // launch the first child -- its exception is ignored for this example (don't do this in practice!)
        val firstChild = launch(CoroutineExceptionHandler { _, _ -> }) {
            log("The first child is failing")
            throw AssertionError("The first child is cancelled")
        }
        // launch the second child
        val secondChild = launch {
            firstChild.join()
            // Cancellation of the first child is not propagated to the second child
            log("The first child is cancelled: ${firstChild.isCancelled}, but the second one is still active")
            try {
                delay(Long.MAX_VALUE)
            } finally {
                // But cancellation of the supervisor is propagated
                log("The second child is cancelled because the supervisor was cancelled")
            }
        }
        // wait until the first child fails & completes
        firstChild.join()
        log("Cancelling the supervisor")
        supervisor.cancel()
        secondChild.join()
    }
}
